# app/core/security.py
from datetime import datetime, timedelta
from typing import Optional

from jose import JWTError, jwt
from passlib.context import CryptContext
from fastapi import Depends, HTTPException, status
from fastapi.security import OAuth2PasswordBearer

from core.config import get_settings

settings = get_settings()

pwd_context = CryptContext(schemes=["argon2"], deprecated="auto")
oauth2_scheme = OAuth2PasswordBearer(tokenUrl="/api/v1/auth/login")

def verify_password(plain_password, hashed_password):
    return pwd_context.verify(plain_password, hashed_password)

def get_password_hash(password):
    return pwd_context.hash(password)

def create_access_token(data: dict, expires_delta: Optional[timedelta] = None):
    to_encode = data.copy()
    expire = datetime.utcnow() + (expires_delta or timedelta(minutes=15))
    to_encode.update({"exp": expire})
    return jwt.encode(to_encode, settings.SECRET_KEY, algorithm=settings.JWT_ALGORITHM)

async def get_current_user(token: str = Depends(oauth2_scheme)):
    credentials_exception = HTTPException(
        status_code=status.HTTP_401_UNAUTHORIZED,
        detail="Could not validate credentials",
        headers={"WWW-Authenticate": "Bearer"},
    )
    try:
        payload = jwt.decode(token, settings.SECRET_KEY, algorithms=[settings.JWT_ALGORITHM])
        username: str = payload.get("sub")
        if username is None:
            raise credentials_exception
        return {"username": username}
    except JWTError:
        raise credentials_exception